Workbook

Sheet 표지
O6: 품질활동 체크리스트
O8: 버전 1.1
O10: 2019.12.13
H12: 승인사항
K13: 성명 / 직급 | O13: 일자 | S13: 서명
H14: 작성자
H15: 검토자
H16: 승인자

Sheet 개정이력
A2: 문 서 이 력
B4: 버전 | C4: 제/개정 내용 | D4: 작성일 | E4: 작성자 | F4: 승인자 | G4: 시행일
B5: 1.1 | C5: 최초 작성 | D5: 2020.06.29 | E5: 박민수
B6: 1.4 | C6: 집계 수정 | D6: 2020.09.03 | E6: 강경철
B7: 1.5 | C7: PM팀, 기술관리팀 의견 수렴하여 현행화 | D7: 2023.02.10 | E7: 이철한
B8: 1.6 | C8: 점검결과 집계 N/A 수식오류 수정 | D8: 2024.03.12 | E8: 이철한

Sheet 품질활동계획
A2: 프로젝트 품질활동 계획
A4: ▣프로젝트 명 | C4: Project 명
A5: ▣프로젝트 PM | C5: PM 성명
A8: 1. 프로젝트 수행 기간
A9: 구분 | C9: 시작일 | D9: 종료일 | E9: 비고
A10: 프로젝트 수행기간 | C10: 43794 | D10: 43945
A12: 2. 품질활동 계획 수립
A13: 구분 | C13: 시작일 | D13: 종료일 | E13: 비고
A14: 품질활동 계획 | B14: 계획 수립 | C14: 43822 | D14: 43826
B15: 1차 활동 (설계완료) | C15: 43850 | D15: 43854
B16: 2차 활동 (배포/이행 후) | C16: 43934 | D16: 43938
A18: 3. 품질감사 기준 | G18: [참고] 품질감사(중간) 대상 기준
A19: 구분 | C19: 대상여부 | D19: 원인 | E19: 비고 | G19: 계약금액 | H19: 계획공수 | I19: 수행기간
A20: 품질감사 계획 | B20: 품질감사(중간) 대상 여부 | C20: O | D20: 계약금액 | E20: 계약금 : 228,000,000원, 계획공수 : 20.55MM | G20: 2억 이상 | H20: 20MM 이상 | I20: 5개월 이상
B21: SI 모듈 포함 여부 | C21: 미포함 | D21: - | G21: ※ 계약금액 기준은 매입분 제외 금액임
B22: On-Site 점검 필요 여부 | C22: 필요 | D22: 원격접근 불가
A23: ※ 계약금액, 계획공수, 수행기간의 3가지 조건 중 한가지 이상 해당하는 프로젝트를 대상으로 중간감사 수행
A25: 4. 품질감사 수행 일정
A26: 구분 | C26: 시작일 | D26: 종료일 | E26: 비고
A27: 품질감사 수행 | B27: 중간 - 설계완료 후 | C27: 43857 | D27: 43861 | E27: 산출물 기반으로 진행
B28: 종료 - 종료보고 전 | C28: 43941 | D28: 43944 | E28: 품질활동 계획서, 회의록 등 관련 산출물 점검

Sheet 점검결과 집계
A1: 점검결과 집계 | J1: 일부적합 가중치
J2: 0.5
A4: 구분 | B4: 단계 | C4: 전체 항목수 | D4: 점검대상 항목수 | E4: 적합 | F4: 일부적합 | G4: 부적합 | H4: N/A | I4: 적합율
A5: 사업관리 | B5: 준비/계획 | C5: =COUNT('사업관리 체크리스트'!A3:A22) -> 20 | D5: =C5-H5 -> 20 | E5: =COUNTIFS('사업관리 체크리스트'!G3:G22,"적합", '사업관리 체크리스트'!H3:H22,"<>N/A") -> 20 | F5: =COUNTIFS('사업관리 체크리스트'!G3:G22,"일부적합", '사업관리 체크리스트'!H3:H22,"<>N/A") -> 0 | G5: =COUNTIFS('사업관리 체크리스트'!G3:G22,"부적합", '사업관리 체크리스트'!H3:H22,"<>N/A") -> 0 | H5: =COUNTIF('사업관리 체크리스트'!H3:H22,"N/A") -> 0 | I5: =IF(D5=0,"-",(E5+(F5*$J$2))/D5) -> 1
B6: 프로젝트 수행/종료 | C6: =COUNT('사업관리 체크리스트'!A23:A35) -> 13 | D6: =C6-H6 -> 13 | E6: =COUNTIFS('사업관리 체크리스트'!G23:G35,"적합",'사업관리 체크리스트'!H23:H35,"<>N/A") -> 13 | F6: =COUNTIFS('사업관리 체크리스트'!G23:G35,"일부적합",'사업관리 체크리스트'!H23:H35,"<>N/A") -> 0 | G6: =COUNTIFS('사업관리 체크리스트'!G23:G35,"부적합",'사업관리 체크리스트'!H23:H35,"<>N/A") -> 0 | H6: =COUNTIF('사업관리 체크리스트'!H23:H35,"N/A") -> 0 | I6: =IF(D6=0,"-",(E6+(F6*$J$2))/D6) -> 1
B7: 합계 | C7: =SUM(C5:C6) -> 33 | D7: =SUM(D5:D6) -> 33 | E7: =SUM(E5:E6) -> 33 | F7: =SUM(F5:F6) -> 0 | G7: =SUM(G5:G6) -> 0 | H7: =SUM(H5:H6) -> 0 | I7: =IF(D7=0,"-",(E7+(F7*$J$2))/D7) -> 1
A10: 구분 | B10: 단계 | C10: 전체 항목수 | D10: 점검대상 항목수 | E10: 적합 | F10: 일부적합 | G10: 부적합 | H10: N/A | I10: 적합율
A11: 개발관리 | B11: 분석단계 | C11: =COUNT('개발관리 체크리스트'!A3:A12) -> 10 | D11: =C11-H11 -> 10 | E11: =COUNTIFS('개발관리 체크리스트'!G3:G12,"적합", '개발관리 체크리스트'!H3:H12,"<>N/A") -> 10 | F11: =COUNTIFS('개발관리 체크리스트'!G3:G12,"일부적합", '개발관리 체크리스트'!H3:H12,"<>N/A") -> 0 | G11: =COUNTIFS('개발관리 체크리스트'!G3:G12,"부적합", '개발관리 체크리스트'!H3:H12,"<>N/A") -> 0 | H11: =COUNTIF('개발관리 체크리스트'!H3:H12,"N/A") -> 0 | I11: =IF(D11=0,"-",(E11+(F11*$J$2))/D11) -> 1
B12: 설계단계 | C12: =COUNT('개발관리 체크리스트'!A13:A36) -> 24 | D12: =C12-H12 -> 24 | E12: =COUNTIFS('개발관리 체크리스트'!G13:G36,"적합", '개발관리 체크리스트'!H13:H36,"<>N/A") -> 24 | F12: =COUNTIFS('개발관리 체크리스트'!G13:G36,"일부적합", '개발관리 체크리스트'!H13:H36,"<>N/A") -> 0 | G12: =COUNTIFS('개발관리 체크리스트'!G13:G36,"부적합", '개발관리 체크리스트'!H13:H36,"<>N/A") -> 0 | H12: =COUNTIF('개발관리 체크리스트'!H13:H36,"N/A") -> 0 | I12: =IF(D12=0,"-",(E12+(F12*$J$2))/D12) -> 1
B13: 구현/테스트단계 | C13: =COUNT('개발관리 체크리스트'!A37:A50) -> 14 | D13: =C13-H13 -> 14 | E13: =COUNTIFS('개발관리 체크리스트'!G37:G50,"적합",'개발관리 체크리스트'!H37:H50,"<>N/A") -> 14 | F13: =COUNTIFS('개발관리 체크리스트'!G37:G50,"일부적합",'개발관리 체크리스트'!H37:H50,"<>N/A") -> 0 | G13: =COUNTIFS('개발관리 체크리스트'!G37:G50,"부적합",'개발관리 체크리스트'!H37:H50,"<>N/A") -> 0 | H13: =COUNTIF('개발관리 체크리스트'!H37:H50,"N/A") -> 0 | I13: =IF(D13=0,"-",(E13+(F13*$J$2))/D13) -> 1
B14: 배포/이행단계 | C14: =COUNT('개발관리 체크리스트'!A51:A64) -> 14 | D14: =C14-H14 -> 14 | E14: =COUNTIFS('개발관리 체크리스트'!G51:G64,"적합",'개발관리 체크리스트'!H51:H64,"<>N/A") -> 14 | F14: =COUNTIFS('개발관리 체크리스트'!G51:G64,"일부적합",'개발관리 체크리스트'!H51:H64,"<>N/A") -> 0 | G14: =COUNTIFS('개발관리 체크리스트'!G51:G64,"부적합",'개발관리 체크리스트'!H51:H64,"<>N/A") -> 0 | H14: =COUNTIF('개발관리 체크리스트'!H51:H64,"N/A") -> 0 | I14: =IF(D14=0,"-",(E14+(F14*$J$2))/D14) -> 1
B15: 합계 | C15: =SUM(C11:C14) -> 62 | D15: =SUM(D11:D14) -> 62 | E15: =SUM(E11:E14) -> 62 | F15: =SUM(F11:F14) -> 0 | G15: =SUM(G11:G14) -> 0 | H15: =SUM(H11:H14) -> 0 | I15: =IF(D15=0,"-",(E15+(F15*$J$2))/D15) -> 1
A18: 품질관리 점검결과 등급 기준

Sheet 사업관리 체크리스트
A1: No | B1: 단계 | C1: 세그먼트 | D1: 태스크 | E1: 체크 산출물 | F1: 상세 체크항목 | G1: 점검 결과
G2: 적합 | H2: 필수여부 | I2: 평가의견
A3: =ROW(A3)-2 -> 1 | B3: 준비/계획 | C3: 프로젝트 착수 | D3: 수행계획 | E3: 수행계획서 | F3: 프로젝트 수행계획서 작성은 되었는가? (고객사에 착수보고 제출시에는 제출용 수행계획서로 대체 가능) | G3: 적합 | H3: 필수
A4: =ROW(A4)-2 -> 2 | F4: 범위 관리 계획은 명확히 표시되어 있는가? - RFP, 요구사항 포함 여부 확인 | G4: 적합 | H4: 필수
A5: =ROW(A5)-2 -> 3 | F5: 자원계획은 명확히 표시되어 있는가?(인력투입계획 필수) -. 자원 : 인력, Software, HW | G5: 적합 | H5: 필수
A6: =ROW(A6)-2 -> 4 | F6: 프로젝트 수행 일정이 정의되어 있는가?(주요 Milestone 수준 명시) | G6: 적합 | H6: 필수
A7: =ROW(A7)-2 -> 5 | F7: 프로젝트 산출물이 명확히 정의되어 있는가? (고객과 협의 내용외에 필수 산출물 정의) | G7: 적합 | H7: 필수
A8: =ROW(A8)-2 -> 6 | F8: 교육 일정, 내용, 대상이 정의되었는가? | G8: 적합 | H8: 필수
A9: =ROW(A9)-2 -> 7 | F9: 주월간 보고 및 단계별 보고 등 전체 보고계획은 정의되었는가? | G9: 적합 | H9: 필수
A10: =ROW(A10)-2 -> 8 | E10: 산출물 테일러링 리스트 | F10: 산출물 테일러링 리스트는 작성되었는가? | G10: 적합 | H10: 필수
A11: =ROW(A11)-2 -> 9 | F11: R&R이 명확히 명시되어 있는가? | G11: 적합 | H11: 필수
A12: =ROW(A12)-2 -> 10 | C12: 계획 | D12: 범위/일정 관리 | E12: WBS | F12: 수행 계획서의 범위가 모두 WBS에 정의되어 있는가? | G12: 적합 | H12: 필수
A13: =ROW(A13)-2 -> 11 | F13: 모듈은 빠짐없이 등록되어있는가? | G13: 적합 | H13: 필수
A14: =ROW(A14)-2 -> 12 | F14: 분석/설계 단계 품질관리 일정은 수립되어 있는가? (Check List/분석/설계 산출물 본사 제출일정) | G14: 적합 | H14: 필수
A15: =ROW(A15)-2 -> 13 | F15: 구현/테스트 단계 품질관리 일정은 수립되어 있는가? (Check List/구현/테스트 산출물 본사 제출일정) | G15: 적합 | H15: 필수
A16: =ROW(A16)-2 -> 14 | F16: 3rd 제품 발주 일정은 수립되어 있는가? | G16: 적합 | H16: 옵션
A17: =ROW(A17)-2 -> 15 | F17: Work Package의 각각의 '담당자' 는 명시되어 있는가? | G17: 적합 | H17: 필수
A18: =ROW(A18)-2 -> 16 | F18: Work Package의 '산출물명' 은 명시되어 있는가? | G18: 적합 | H18: 필수
A19: =ROW(A19)-2 -> 17 | F19: 집행계획 일정은 수립되어 있는가? | G19: 적합 | H19: 필수
A20: =ROW(A20)-2 -> 18 | F20: 고객 교육과 관련한 일정,대상,범위가 수립되어 있는가? | G20: 적합 | H20: 필수
A21: =ROW(A21)-2 -> 19 | F21: 고객 인수인계 일정이 명시되어 있는가 - 인수인계와 상응하는(운영자/관리자 교육등) Activity 일정 수립 등 | G21: 적합 | H21: 필수
A22: =ROW(A22)-2 -> 20 | F22: 5M/D(40M/H)를 초과하는 Task가 존재하는가? (분석,설계,개발 항목에 적용. 마이그레이션 및 테스트, 안정화 단계는 예외 ) | G22: 적합 | H22: 필수
A23: =ROW(A23)-2 -> 21 | B23: 프로젝트 수행 | C23: 프로젝트 수행 | D23: 범위/일정 관리 | E23: 회의록/activity관리대장 또는 PMS실행항목 | F23: 프로젝트 수행 중 고객사와 회의한 결과가 기록된 회의록이 작성 되었는가? | G23: 적합 | H23: 필수
A24: =ROW(A24)-2 -> 22 | F24: 프로젝트 수행 규모에 비하여 작성된 문서의 개수는 적절한가? (최소 모듈별 1개 이상 존재) | G24: 적합 | H24: 필수
A25: =ROW(A25)-2 -> 23 | F25: 회의록에 반드시 포함되어야 할 사항이 기재되었는가? (회의명, 회의일시, 회의장소, 주제, 참석자, 작성자, 내용 등) | G25: 적합 | H25: 필수
A26: =ROW(A26)-2 -> 24 | F26: 주요 내용이 포함되어 있는가? (회의내용, 결정사항, 검토사항, 실행항목 등) | G26: 적합 | H26: 필수
A27: =ROW(A27)-2 -> 25 | F27: 회의에서 도출된 실행항목에 대하여 관리 대장을 작성하였는가? - 실행항목이 존재한다면 관리 대장을 통하여 실행에 대한 추적이 가능해야 함 (회의록activity관리대장 또는 PMS 실행항목[다운로드]) - 기본 템플릿 제공.(템플릿 미사용시 다른 산출물로 대체 가능) | G27: 적합 | H27: 필수
A28: =ROW(A28)-2 -> 26 | D28: 일정진척관리 | E28: WBS | F28: 해당 단계에서 수행해야하는 모든 Activity와 Task가 완료되었는가? | G28: 적합 | H28: 필수
A29: =ROW(A29)-2 -> 27 | F29: 분석/설계 단계 품질관리는 수행하였는가? | G29: 적합 | H29: 필수
A30: =ROW(A30)-2 -> 28 | F30: 구현/테스트 단계 품질관리는 수행하였는가? | G30: 적합 | H30: 필수
A31: =ROW(A31)-2 -> 29 | D31: 자원관리 | E31: 투입현황/주요현황 | F31: 프로젝트 규모,공수,비용,일정이 정기적으로 추적되는가? (PMS 주간실적 현황 관리) | G31: 적합 | H31: 필수
A32: =ROW(A32)-2 -> 30 | D32: 위험/이슈관리 | E32: 이슈 및 위험목록 | F32: 리스크 및 이슈 관리가 되었는가? - 현황, 대응방안 등 (PMS 관리 또는 별도자료 관리) | G32: 적합 | H32: 필수
A33: =ROW(A33)-2 -> 31 | D33: 의사소통 | E33: 고객사 주간(또는 월간 포함)보고 | F33: 프로젝트 진척보고는 베이스라인,실적,예측 등을 포함하는가? | G33: 적합 | H33: 필수
A34: =ROW(A34)-2 -> 32 | B34: 프로젝트 종료 | C34: 프로젝트 종료 | D34: 종료보고 | E34: 프로젝트 종료보고서 | F34: 프로젝트 평가를 위한 (내부)종료보고서를 작성하였는가? | G34: 적합 | H34: 필수
A35: =ROW(A35)-2 -> 33 | D35: 인수인계 실시 | E35: CS사업팀 인수인계 | F35: CS사업팀 인수인계를 실시하였는가? | G35: 적합 | H35: 필수

Sheet 개발관리 체크리스트
A1: No | B1: 단계 | C1: 세그먼트 | D1: 태스크 | E1: 체크 항목 | F1: 상세 체크항목 | G1: 점검 결과
G2: 적합 | H2: 필수여부 | I2: 평가의견
A3: =ROW(A3)-2 -> 1 | B3: 분석 | C3: 요구사항 | D3: 요구사항 정의 | E3: 요구사항 정의서/추적표 | F3: 요구사항이 명확히 기술되었는가? - RFP에 정의된 요구사항에 대하여 누락 확인 - 표현의 모호성 제거해야 함( '~등' 과 같은 단어) | G3: 적합 | H3: 필수
A4: =ROW(A4)-2 -> 2 | F4: 요구사항 ID가 명확히 기입되었는가? | G4: 적합 | H4: 필수
A5: =ROW(A5)-2 -> 3 | F5: 요구사항의 출처가 명확히 기입되어 있는가? | G5: 적합 | H5: 필수
A6: =ROW(A6)-2 -> 4 | F6: 매핑/GAP분석의 GAP설명과 대응방안이 구체적으로 작성되어 있는가? | G6: 적합 | H6: 필수
A7: =ROW(A7)-2 -> 5 | F7: 수용여부는 명확히 기입하였는가? - 수용여부가 '부분수용', '불가' 일 경우 그 근거가 '비고' 란에 작성되어있는가? | G7: 적합 | H7: 필수
A8: =ROW(A8)-2 -> 6 | F8: 요구사항에 대하여 기능, 비기능의 구분이 명확한가? | G8: 적합 | H8: 필수
A9: =ROW(A9)-2 -> 7 | F9: 비기능' 요구사항의 경우 구현 결과에 대하여 고객과 협의된 회의록등 확인할 수 있는 근거가 등록되어 있는가? (ex:'웹페이지 성능개선의 경우 3초이내 화면이 로딩되어야 함' 과 같은 고객과의 협의된 사항 필요) | G9: 적합 | H9: 옵션
A10: =ROW(A10)-2 -> 8 | F10: 요구사항 정의서를 고객에게 제출하였는가? - 향후 분쟁시 근거가 될 수 있도록 e-mail 로 반드시 제출 및 고객의 이의사항에 대한 추적 가능해야 함. | G10: 적합 | H10: 필수
A11: =ROW(A11)-2 -> 9 | D11: 현황분석 | E11: 현황분석서 | F11: AS-IS 메뉴구조도 작성이 되었는가? | G11: 적합 | H11: 옵션
A12: =ROW(A12)-2 -> 10 | F12: AS-IS 기능리스트는 작성이 되었는가? - TO-BE 지원여부에 대한 GAP 차이 체크 확인 | G12: 적합 | H12: 옵션
A13: =ROW(A13)-2 -> 11 | B13: 설계 | C13: UI설계 | D13: 메뉴/화면 설계 | E13: 메뉴구조도 | F13: 메뉴 구조도 작성이 되었는가? | G13: 적합 | H13: 필수
A14: =ROW(A14)-2 -> 12 | E14: 화면정의서 | F14: 화면정의서 표준 템플릿을 사용하여 작성하였는가? | G14: 적합 | H14: 필수
A15: =ROW(A15)-2 -> 13 | F15: 화면 ID 가 정확히 기입되어 있는가? | G15: 적합 | H15: 필수
A16: =ROW(A16)-2 -> 14 | F16: 입력항목이 있는 경우 필수입력값이 명시되어 있는가? | G16: 적합 | H16: 옵션
A17: =ROW(A17)-2 -> 15 | F17: 버튼 혹은 이미지등의 링크에 PoP UP 이벤트 존재시 해당 Popup 기능이 설계된 Page 번호 명시 되었는가? | G17: 적합 | H17: 옵션
A18: =ROW(A18)-2 -> 16 | C18: 시스템 설계 | D18: 데이터베이스 설계 | E18: 테이블 정의서 | F18: 기본 DB 스키마 변경, SI 모듈 존재 시 해당 Table에 대한 정의서 작성이 되었는가? | G18: 적합 | H18: 옵션
A19: =ROW(A19)-2 -> 17 | F19: Primary Key, 칼럼의 형태, 길이, NULL 여부가 표현되도록 작성하였는가? | G19: 적합 | H19: 옵션
A20: =ROW(A20)-2 -> 18 | D20: 어플리케이션 설계 | E20: 인터페이스 정의서 | F20: 인터페이스 목록 또는 정의서 작성이 되었는가? | G20: 적합 | H20: 옵션
A21: =ROW(A21)-2 -> 19 | F21: 인터페이스 ID 가 명확히 기재되어 있는가? | G21: 적합 | H21: 옵션
A22: =ROW(A22)-2 -> 20 | E22: 프로그램 목록(SI모듈) | F22: 프로그램 목록은 작성 되었는가? | G22: 적합 | H22: 옵션
A23: =ROW(A23)-2 -> 21 | F23: 프로그램 목록 ID가 기재되어 있는가? | G23: 적합 | H23: 옵션
A24: =ROW(A24)-2 -> 22 | C24: 마이그레이션 설계 | D24: 마이그레이션 전략수립 | E24: 마이그레이션 계획서 | F24: 마이그레이션 계획서 작성은 되었는가? | G24: 적합 | H24: 옵션
A25: =ROW(A25)-2 -> 23 | F25: 마이그레이션 범위(종류 & 분량) 가 명시되어있는가? | G25: 적합 | H25: 옵션
A26: =ROW(A26)-2 -> 24 | F26: 마이그레이션 절차 및 일정이 명시되어 있는가? | G26: 적합 | H26: 옵션
A27: =ROW(A27)-2 -> 25 | F27: 마이그레이션 검증 방안에 대하여 명시되어 있는가? | G27: 적합 | H27: 옵션
A28: =ROW(A28)-2 -> 26 | E28: 매핑정의서 | F28: 매핑정의서는 정확하게 작성이 되었는가? | G28: 적합 | H28: 옵션
A29: =ROW(A29)-2 -> 27 | C29: 테스트 설계 | D29: 테스트 계획 수립 | E29: 테스트 계획서 | F29: 테스트 계획서 작성은 되었는가? | G29: 적합 | H29: 필수
A30: =ROW(A30)-2 -> 28 | F30: 테스트 환경이 명시되어 있는가? | G30: 적합 | H30: 필수
A31: =ROW(A31)-2 -> 29 | F31: 테스트 일정이 명시되어 있는가? | G31: 적합 | H31: 필수
A32: =ROW(A32)-2 -> 30 | F32: 테스트 담당자가 명시되어 있는가? | G32: 적합 | H32: 필수
A33: =ROW(A33)-2 -> 31 | D33: 단위테스트 설계 | E33: 단위테스트 케이스 | F33: 단위테스트 케이스 작성이 되었는가? (모듈별 설치 체크리스트 포함) | G33: 적합 | H33: 필수
A34: =ROW(A34)-2 -> 32 | F34: 요구사항에 정의된 기능요구사항에 대하여 단위테스트 케이스가 작성이 되었는가? | G34: 적합 | H34: 필수
A35: =ROW(A35)-2 -> 33 | C35: 단계완료 | D35: 요구사항 추적 | E35: 요구사항 추적표 | F35: 요구사항 추적표는 작성이 되었는가? | G35: 적합 | H35: 옵션
A36: =ROW(A36)-2 -> 34 | F36: 기능 요구사항은 요구사항 ID와 화면ID 혹은 매뉴얼의 Page 가 정확히 추적되는가? | G36: 적합 | H36: 옵션
A37: =ROW(A37)-2 -> 35 | B37: 구현/테스트 | C37: 테스트 | D37: 단위테스트 실시 | E37: 단위테스트 결과 | F37: 단위테스트 케이스 결과서가 작성이 되었는가? (모듈별 설치 테스트 수행 포함) | G37: 적합 | H37: 필수
A38: =ROW(A38)-2 -> 36 | F38: 단위테스트 케이스 결과서에 테스트결과가 기록되어 있는가? | G38: 적합 | H38: 필수
A39: =ROW(A39)-2 -> 37 | F39: 오류가 발생한 항목에 대해 결함유형 및 결함에 대한 조치결과 및 완료 일자가 기재되었는가? | G39: 적합 | H39: 필수
A40: =ROW(A40)-2 -> 38 | D40: 통합테스트 설계 | E40: 통합테스트 시나리오 | F40: 통합테스트 시나리오 작성은 되었는가? | G40: 적합 | H40: 필수
...

Sheet 작성방법
A1: 작성방법
A2: 1. 품질감사 시점
A3: - 설계 종료 시점 : 준비/계획, 분석단계, 설계단계
A4: - 구현 완료 혹은 오픈 전 : 구현/테스트 단계, 배포/이행 단계
A5: 2. 품질활동 체크리스트 테일러링
A6: - 필수여부가 "N/A" 일 경우 반드시 평가의견에 근거를 제시해야 한다.
A7: - 임의로 체크항목을 지워서는 안되며, 필수 항목은 반드시 지켜야 함
A8: 3. 품질활동 수행 후 품질활동 결과를 기록한다.
A9: - 판정에서 적합, 일부적합, 부적합 중 하나를 선택한다.
A10: - 적합, 일부적합, 부적합은 아래와 같은 기준으로 판단한다.
A11: • 적합 : 체크항목의 내용과 관련된 근거자료가 존재하고, 체크항목의 내용과 조건에 100% 부합될 경우
A12: • 일부적합 : 체크항목의 내용과 관련된 근거자료가 존재하고, 체크항목의 내용과 조건에 60% 이상 부합된다고 판단될 경우
... A14: - 적합이 아닌 항목에 대해서는 "결함및시정조치목록"에 기록한다.
